I'm sorry, but an uncaught exception occurred.

While running game code:
  File "game/script.rpy", line 8, in script
    "LOGG:script.rpy: [player.place] [player.energy] "
KeyError: u'player'

-- Full Traceback ------------------------------------------------------------

Full traceback:
  File "game/script.rpy", line 8, in script
    "LOGG:script.rpy: [player.place] [player.energy] "
  File "/home/gkiss/Misc/renpy-6.99.14.3-sdk/renpy/ast.py", line 652, in execute
    renpy.exports.say(who, what, interact=self.interact, *args, **kwargs)
  File "/home/gkiss/Misc/renpy-6.99.14.3-sdk/renpy/exports.py", line 1180, in say
    who(what, *args, **kwargs)
  File "/home/gkiss/Misc/renpy-6.99.14.3-sdk/renpy/character.py", line 1003, in __call__
    what = what_pattern.replace("[what]", sub(what, translate=translate))
  File "/home/gkiss/Misc/renpy-6.99.14.3-sdk/renpy/character.py", line 985, in sub
    return renpy.substitutions.substitute(s, scope=scope, force=force, translate=translate)[0]
  File "/home/gkiss/Misc/renpy-6.99.14.3-sdk/renpy/substitutions.py", line 242, in substitute
    s = formatter.vformat(s, (), kwargs)
  File "/home/tom/ab/x64lucid-deps/install/lib/python2.7/string.py", line 563, in vformat
  File "/home/tom/ab/x64lucid-deps/install/lib/python2.7/string.py", line 585, in _vformat
  File "/home/tom/ab/x64lucid-deps/install/lib/python2.7/string.py", line 646, in get_field
  File "/home/tom/ab/x64lucid-deps/install/lib/python2.7/string.py", line 605, in get_value
KeyError: u'player'

Linux-4.13.0-38-generic-x86_64-with-debian-stretch-sid
Ren'Py 6.99.14.3.3347
abstract 1.0
Thu Apr 19 07:42:33 2018
